<?xml version="1.0" encoding="utf-8"?>
<!-- This URDF was automatically created by SolidWorks to URDF Exporter!
    Modified by Guangzhe in order to work with RoboticsToolKit
    For more information, please see http://wiki.ros.org/sw_urdf_exporter -->
<robot name="mg400_description">
    <link name="base_link">
        <inertial>
            <origin xyz="0.000600637001378879 -2.53487071137343E-07 0.0560927888040551" rpy="0 0 0"/>
            <mass value="3.62164811695094"/>
            <inertia
                    ixx="0.0126582175296405"
                    ixy="6.66832041405407E-08"
                    ixz="-3.52548281362717E-06"
                    iyy="0.0145891535260188"
                    iyz="5.15901657460475E-08"
                    izz="0.0195045116656827"/>
        </inertial>
        <visual>
            <origin xyz="0 0 0" rpy="0 0 0"/>
            <geometry>
                <mesh filename="package://mg400_description/meshes/base_link.STL"/>
            </geometry>
            <material name="">
                <color rgba="1 1 1 1"/>
            </material>
        </visual>
        <collision>
            <origin xyz="0 0 0" rpy="0 0 0"/>
            <geometry>
                <mesh filename="package://mg400_description/meshes/base_link.STL"/>
            </geometry>
        </collision>
    </link>

    <link name="link1">
        <inertial>
            <origin xyz="-0.0046209286967387 -6.88107982318643E-05 0.0709919358465827" rpy="0 0 0"/>
            <mass value="1.77056222753813"/>
            <inertia
                    ixx="0.00605885293080088"
                    ixy="0.000156081820035162"
                    ixz="-0.00021785654850453"
                    iyy="0.00579381982249127"
                    iyz="6.20876898015621E-05"
                    izz="0.00741058257251941"/>
        </inertial>
        <visual>
            <origin xyz="0 0 0" rpy="0 0 0"/>
            <geometry>
                <mesh filename="package://mg400_description/meshes/link1.STL"/>
            </geometry>
            <material name="">
                <color rgba="1 1 1 1"/>
            </material>
        </visual>
        <collision>
            <origin xyz="0 0 0" rpy="0 0 0"/>
            <geometry>
                <mesh filename="package://mg400_description/meshes/link1.STL"/>
            </geometry>
        </collision>
    </link>

    <joint name="j1" type="revolute">
        <origin xyz="-0.00500000000000002 0 0.109" rpy="0 0 0"/>
        <parent link="base_link"/>
        <child link="link1"/>
        <axis xyz="0 0 1"/>
        <limit lower="-3.14" upper="3.14" effort="0" velocity="0"/>
    </joint>

    <link name="link2_1">
        <inertial>
            <origin xyz="-0.00321788524756698 0.0352926570826593 0.0596131328734945" rpy="0 0 0"/>
            <mass value="0.0866115884541459"/>
            <inertia
                    ixx="0.000338551627157209"
                    ixy="-2.78858228577314E-09"
                    ixz="1.05212346076681E-05"
                    iyy="0.000307789653713489"
                    iyz="-1.36109590152488E-06"
                    izz="3.89949940178023E-05"/>
        </inertial>
        <visual>
            <origin xyz="0 0 0" rpy="0 0 0"/>
            <geometry>
                <mesh filename="package://mg400_description/meshes/link2_1.STL"/>
            </geometry>
            <material name="">
                <color rgba="1 1 1 1"/>
            </material>
        </visual>
        <collision>
            <origin xyz="0 0 0" rpy="0 0 0"/>
            <geometry>
                <mesh filename="package://mg400_description/meshes/link2_1.STL"/>
            </geometry>
        </collision>
    </link>

    <joint name="j2" type="revolute">
        <origin xyz="0.0435007595118091 -0.0357748756218899 0.118995682641123" rpy="0 0 0"/>
        <parent link="link1"/>
        <child link="link2_1"/>
        <axis xyz="0 1 0"/>
        <limit lower="-0.14" upper="1.39" effort="0" velocity="0"/>
    </joint>

    <link name="link3_1">
        <inertial>
            <origin xyz="0.0821679417596488 0.000113044685842874 -0.00333758753063973" rpy="0 0 0"/>
            <mass value="0.0375214831045061"/>
            <inertia
                    ixx="2.54761091812684E-06"
                    ixy="3.73102654491378E-07"
                    ixz="-2.02625705871199E-06"
                    iyy="0.000164234314177935"
                    iyz="-1.44731096825347E-08"
                    izz="0.000164331500854172"/>
        </inertial>
        <visual>
            <origin xyz="0 0 0" rpy="0 0 0"/>
            <geometry>
                <mesh filename="package://mg400_description/meshes/link3_1.STL"/>
            </geometry>
            <material name="">
                <color rgba="1 1 1 1"/>
            </material>
        </visual>
        <collision>
            <origin xyz="0 0 0" rpy="0 0 0"/>
            <geometry>
                <mesh filename="package://mg400_description/meshes/link3_1.STL"/>
            </geometry>
        </collision>
    </link>

    <link name="link4_1">
        <inertial>
            <origin xyz="0.0387878182928232 0.0170848333998282 -0.0024610990490942" rpy="0 0 0"/>
            <mass value="0.0628979533925801"/>
            <inertia
                    ixx="4.78483605712844E-05"
                    ixy="1.42081909356751E-07"
                    ixz="8.32917079044309E-06"
                    iyy="5.42362047732042E-05"
                    iyz="-2.90608446019989E-08"
                    izz="3.36120409842199E-05"/>
        </inertial>
        <visual>
            <origin xyz="0 0 0" rpy="0 0 0"/>
            <geometry>
                <mesh filename="package://mg400_description/meshes/link4_1.STL"/>
            </geometry>
            <material name="">
                <color rgba="1 1 1 1"/>
            </material>
        </visual>
        <collision>
            <origin xyz="0 0 0" rpy="0 0 0"/>
            <geometry>
                <mesh filename="package://mg400_description/meshes/link4_1.STL"/>
            </geometry>
        </collision>
    </link>


    <joint name="j3" type="revolute">
        <origin xyz="-0.0010512570171516 0.0357748756218898 0.175001164344716" rpy="0 0 0"/>
        <parent link="link2_1"/>
        <child link="link3_1"/>
        <axis xyz="0 1 0"/>
        <limit lower="0" upper="1.39" effort="0" velocity="0"/>
    </joint>

    <joint name="j4_1" type="revolute">
        <origin xyz="0.174969784055705 -0.0170000000000335 0.00325187137614585" rpy="0 0 0"/>
        <parent link="link3_1"/>
        <child link="link4_1"/>
        <axis xyz="0 1 0"/>
        <limit lower="-3.14" upper="3.14" effort="0" velocity="0"/>
        <mimic joint="j4_2" multiplier="-1" />
    </joint>


</robot>